Workbook

Sheet Cover
A1: Qualcomm Financial Revenue Forecast & Earnings Variance Analysis
A2: Forecasting Qualcomm's shift from phones to cars & AI | $ in millions unless noted
A4: Active scenario | B4: =Assumptions!C5 -> Base
A5: Model checks | B5: =Checks!C4 -> ALL OK
A7: Tab guide
A8: Assumptions | B8: Scenario selector (1=Base, 2=Bull, 3=Bear) and every forecast driver with rationale
A9: Actuals | B9: Reported segment revenue and EBT, FY24 Q1 - FY26 Q3, from earnings releases (S1-S11)
A10: Guidance | B10: Company revenue guidance ranges issued one quarter ahead, FY24 Q2 - FY26 Q4
A11: Variance | B11: Actual vs. guidance midpoint by segment: $ and % beat/miss, position in range
A12: Forecast | B12: Quarterly actuals + forecast FY26 Q4 - FY27 Q4 driven by the active scenario
A13: Summary | B13: Fiscal-year roll-up and the core question: does diversification offset handset decline?
A14: Scenarios | B14: FY26E / FY27E revenue and EBT under Base, Bull and Bear side by side
A15: Sensitivity | B15: FY27E revenue across handset growth x automotive growth
A16: Checks | B16: Integrity tests: stream tie-outs, guidance math, annual roll-ups, selector
A17: Tableau_Revenue | B17: Long-format revenue by stream and quarter (actual + forecast) for Tableau
A18: Tableau_Guidance | B18: Long-format guidance vs. actual/forecast for Tableau
A20: Color legend
A21: 1234 | B21: Blue = hardcoded input from a filing or an analyst assumption (edit these)
A22: 1234 | B22: Black = formula
A23: 1234 | B23: Green = link to another tab
B24: Yellow fill = key lever (scenario selector)
B25: Grey fill = forecast period
A27: Disclaimer
B28: Independent portfolio project built solely from public information (Qualcomm earnings releases and SEC filings). Not affiliated with or endorsed by Qualcomm. Forecast drivers are analyst assumptions, not company data. Not investment advice.

Sheet Assumptions
A1: Assumptions
A2: All forecast drivers. Change B5 to switch scenarios; edit blue cells to test your own view.
A5: Scenario selector (1=Base, 2=Bull, 3=Bear) | B5: 1 | C5: =CHOOSE(B5,"Base","Bull","Bear") -> Base
A7: Driver | B7: Applies to | C7: Base | D7: Bull | E7: Bear | F7: Active | G7: Rationale / source
A8: Handsets revenue, YoY growth | B8: FY26 Q4 | C8: -0.27 | D8: -0.22 | E8: -0.32 | F8: =CHOOSE($B$5,C8,D8,E8) -> -0.27 | G8: Calibrated so Base QCT lands near the FY26 Q4 guidance midpoint ($8.4B-$9.0B, S11). Handsets fell 13% (Q2) and 20% (Q3) YoY; management expects iPhone modem share materially below its prior 20% estimate, and FY25 Q4 is a tough comparison.
A9: Handsets revenue, YoY growth | B9: FY27 | C9: -0.12 | D9: -0.05 | E9: -0.2 | F9: =CHOOSE($B$5,C9,D9,E9) -> -0.12 | G9: Analyst assumption: continued Apple modem roll-off and memory-cost pressure on Android OEM builds, easing as comparisons reset.
A10: Automotive revenue, YoY growth | B10: FY26 Q4 | C10: 0.6 | D10: 0.65 | E10: 0.5 | F10: =CHOOSE($B$5,C10,D10,E10) -> 0.6 | G10: Management commentary after Q3 FY26 pointed to roughly 60% YoY automotive growth in Q4; FY26 Q3 grew 61% (S11).
A11: Automotive revenue, YoY growth | B11: FY27 | C11: 0.3 | D11: 0.4 | E11: 0.2 | F11: =CHOOSE($B$5,C11,D11,E11) -> 0.3 | G11: Analyst assumption: growth decelerates off a larger base; exit-rate target raised to ~$7B annualized for FY26.
A12: IoT revenue, YoY growth | B12: FY26 Q4 | C12: 0.09 | D12: 0.12 | E12: 0.05 | F12: =CHOOSE($B$5,C12,D12,E12) -> 0.09 | G12: IoT grew 9% YoY in both FY26 Q2 and Q3 (S10, S11).
A13: IoT revenue, YoY growth | B13: FY27 | C13: 0.1 | D13: 0.15 | E13: 0.05 | F13: =CHOOSE($B$5,C13,D13,E13) -> 0.1 | G13: Analyst assumption: industrial/robotics and edge-AI product cycles; Bull adds early data center contribution.
A14: QTL revenue, YoY growth | B14: FY26 Q4 | C14: -0.08 | D14: -0.01 | E14: -0.14 | F14: =CHOOSE($B$5,C14,D14,E14) -> -0.08 | G14: Calibrated to FY26 Q4 QTL guidance $1.2B-$1.4B (S11) vs. $1,409M in FY25 Q4.
A15: QTL revenue, YoY growth | B15: FY27 | C15: -0.03 | D15: 0.01 | E15: -0.07 | F15: =CHOOSE($B$5,C15,D15,E15) -> -0.03 | G15: Analyst assumption: licensing tracks handset units; FY26 Q3 QTL was down 3% YoY.
A16: QCT EBT margin | B16: FY26 Q4 | C16: 0.24 | D16: 0.25 | E16: 0.23 | F16: =CHOOSE($B$5,C16,D16,E16) -> 0.24 | G16: FY26 Q4 guidance: QCT EBT margin 23%-25% (S11).
A17: QCT EBT margin | B17: FY27 | C17: 0.26 | D17: 0.29 | E17: 0.23 | F17: =CHOOSE($B$5,C17,D17,E17) -> 0.26 | G17: Analyst assumption: FY24-FY26 quarterly QCT margins ranged 26%-32%; Bear keeps memory-cost pressure.
A18: QTL EBT margin | B18: FY26 Q4 | C18: 0.7 | D18: 0.72 | E18: 0.67 | F18: =CHOOSE($B$5,C18,D18,E18) -> 0.7 | G18: QTL EBT margin ran 69%-77% FY24-FY26 (Actuals tab).
A19: QTL EBT margin | B19: FY27 | C19: 0.7 | D19: 0.73 | E19: 0.67 | F19: =CHOOSE($B$5,C19,D19,E19) -> 0.7 | G19: Analyst assumption: stable licensing margin.
A21: Method: each forecast quarter = same quarter prior year x (1 + YoY growth). Using YoY on the same quarter preserves Qualcomm's seasonality (strong fiscal Q1 holiday handset builds).

Sheet Actuals
A1: Actuals
A2: Reported results, $ in millions. Source: Qualcomm quarterly earnings releases (see docs/sources.csv).
A4: Line item | B4: Unit | C4: FY24 Q1 | D4: FY24 Q2 | E4: FY24 Q3 | F4: FY24 Q4 | G4: FY25 Q1 | H4: FY25 Q2 | I4: FY25 Q3 | J4: FY25 Q4 | K4: FY26 Q1 | L4: FY26 Q2 | M4: FY26 Q3
A5: Period end | C5: 2023-12-24 | D5: 2024-03-24 | E5: 2024-06-23 | F5: 2024-09-29 | G5: 2024-12-29 | H5: 2025-03-30 | I5: 2025-06-29 | J5: 2025-09-28 | K5: 2025-12-28 | L5: 2026-03-29 | M5: 2026-06-28
A6: Source ID | C6: S1 | D6: S2 | E6: S3 | F6: S4 | G6: S5 | H6: S6 | I6: S7 | J6: S8 | K6: S9 | L6: S10 | M6: S11
A8: Revenue ($mm)
A9: Handsets | B9: $mm | C9: 6687 | D9: 6180 | E9: 5899 | F9: 6096 | G9: 7574 | H9: 6929 | I9: 6328 | J9: 6961 | K9: 7824 | L9: 6024 | M9: 5086
A10: Automotive | B10: $mm | C10: 598 | D10: 603 | E10: 811 | F10: 899 | G10: 961 | H10: 959 | I10: 984 | J10: 1053 | K10: 1101 | L10: 1326 | M10: 1588
A11: IoT | B11: $mm | C11: 1138 | D11: 1243 | E11: 1359 | F11: 1683 | G11: 1549 | H11: 1581 | I11: 1681 | J11: 1807 | K11: 1688 | L11: 1726 | M11: 1830
A12: QCT revenue (reported) | B12: $mm | C12: 8423 | D12: 8026 | E12: 8069 | F12: 8678 | G12: 10084 | H12: 9469 | I12: 8993 | J12: 9821 | K12: 10613 | L12: 9076 | M12: 8504
A13: QTL revenue | B13: $mm | C13: 1460 | D13: 1318 | E13: 1273 | F13: 1521 | G13: 1535 | H13: 1319 | I13: 1318 | J13: 1409 | K13: 1592 | L13: 1382 | M13: 1278
A14: QCT + QTL revenue | B14: $mm | C14: =C12+C13 -> 9883 | D14: =D12+D13 -> 9344 | E14: =E12+E13 -> 9342 | F14: =F12+F13 -> 10199 | G14: =G12+G13 -> 11619 | H14: =H12+H13 -> 10788 | I14: =I12+I13 -> 10311 | J14: =J12+J13 -> 11230 | ... M14: =M12+M13 -> 9782
A16: Earnings before taxes ($mm)
A17: QCT EBT | B17: $mm | C17: 2593 | D17: 2288 | E17: 2181 | F17: 2465 | G17: 3246 | H17: 2857 | I17: 2671 | J17: 2896 | K17: 3302 | L17: 2465 | M17: 2192
A18: QTL EBT | B18: $mm | C18: 1080 | D18: 933 | E18: 894 | F18: 1120 | G18: 1158 | H18: 929 | I18: 942 | J18: 1015 | K18: 1231 | L18: 994 | M18: 881
A19: QCT + QTL EBT | B19: $mm | C19: =C17+C18 -> 3673 | D19: =D17+D18 -> 3221 | E19: =E17+E18 -> 3075 | F19: =F17+F18 -> 3585 | G19: =G17+G18 -> 4404 | H19: =H17+H18 -> 3786 | I19: =I17+I18 -> 3613 | J19: =J17+J18 -> 3911 | ... M19: =M17+M18 -> 3073
A21: Margins
A22: QCT EBT margin | B22: % | C22: =IF(C12=0,0,C17/C12) -> 0.30784756 | D22: =IF(D12=0,0,D17/D12) -> 0.28507351 | E22: =IF(E12=0,0,E17/E12) -> 0.27029372 | F22: =IF(F12=0,0,F17/F12) -> 0.28405162 | G22: =IF(G12=0,0,G17/G12) -> 0.32189607 | H22: =IF(H12=0,0,H17/H12) -> 0.30172141 | I22: =IF(I12=0,0,I17/I12) -> 0.29700878 | J22: =IF(J12=0,0,J17/J12) -> 0.29487832 | ... M22: =IF(M12=0,0,M17/M12) -> 0.25776105
A23: QTL EBT margin | B23: % | C23: =IF(C13=0,0,C18/C13) -> 0.73972603 | D23: =IF(D13=0,0,D18/D13) -> 0.70789074 | E23: =IF(E13=0,0,E18/E13) -> 0.70227808 | F23: =IF(F13=0,0,F18/F13) -> 0.73635766 | G23: =IF(G13=0,0,G18/G13) -> 0.75439739 | H23: =IF(H13=0,0,H18/H13) -> 0.70432146 | I23: =IF(I13=0,0,I18/I13) -> 0.71471927 | J23: =IF(J13=0,0,J18/J13) -> 0.72036906 | ... M23: =IF(M13=0,0,M18/M13) -> 0.68935837
A25: YoY growth (same quarter prior year)
A26: Handsets | B26: % | C26: n/a | D26: n/a | E26: n/a | F26: n/a | G26: =IF(C9=0,0,G9/C9-1) -> 0.13264543 | H26: =IF(D9=0,0,H9/D9-1) -> 0.12119741 | I26: =IF(E9=0,0,I9/E9-1) -> 0.072724191 | J26: =IF(F9=0,0,J9/F9-1) -> 0.14189633 | K26: =IF(G9=0,0,K9/G9-1) -> 0.033007658 | L26: =IF(H9=0,0,L9/H9-1) -> -0.13061048 | M26: =IF(I9=0,0,M9/I9-1) -> -0.19627054
A27: Automotive | B27: % | C27: n/a | D27: n/a | E27: n/a | F27: n/a | G27: =IF(C10=0,0,G10/C10-1) -> 0.60702341 | H27: =IF(D10=0,0,H10/D10-1) -> 0.59038143 | I27: =IF(E10=0,0,I10/E10-1) -> 0.21331689 | J27: =IF(F10=0,0,J10/F10-1) -> 0.17130145 | K27: =IF(G10=0,0,K10/G10-1) -> 0.14568158 | L27: =IF(H10=0,0,L10/H10-1) -> 0.3826903 | M27: =IF(I10=0,0,M10/I10-1) -> 0.61382114
A28: IoT | B28: % | C28: n/a | D28: n/a | E28: n/a | F28: n/a | G28: =IF(C11=0,0,G11/C11-1) -> 0.36115993 | H28: =IF(D11=0,0,H11/D11-1) -> 0.27192277 | I28: =IF(E11=0,0,I11/E11-1) -> 0.23693893 | J28: =IF(F11=0,0,J11/F11-1) -> 0.073677956 | K28: =IF(G11=0,0,K11/G11-1) -> 0.089735313 | L28: =IF(H11=0,0,L11/H11-1) -> 0.091714105 | M28: =IF(I11=0,0,M11/I11-1) -> 0.088637716
A29: QCT revenue | B29: % | C29: n/a | D29: n/a | E29: n/a | F29: n/a | G29: =IF(C12=0,0,G12/C12-1) -> 0.19719815 | H29: =IF(D12=0,0,H12/D12-1) -> 0.17979068 | I29: =IF(E12=0,0,I12/E12-1) -> 0.11451233 | J29: =IF(F12=0,0,J12/F12-1) -> 0.13171238 | K29: =IF(G12=0,0,K12/G12-1) -> 0.052459342 | L29: =IF(H12=0,0,L12/H12-1) -> -0.041503855 | M29: =IF(I12=0,0,M12/I12-1) -> -0.054375625
A30: QTL revenue | B30: % | C30: n/a | D30: n/a | E30: n/a | F30: n/a | G30: =IF(C13=0,0,G13/C13-1) -> 0.051369863 | H30: =IF(D13=0,0,H13/D13-1) -> 0.00075872534 | I30: =IF(E13=0,0,I13/E13-1) -> 0.035349568 | J30: =IF(F13=0,0,J13/F13-1) -> -0.073635766 | K30: =IF(G13=0,0,K13/G13-1) -> 0.03713355 | L30: =IF(H13=0,0,L13/H13-1) -> 0.047763457 | M30: =IF(I13=0,0,M13/I13-1) -> -0.030349014
A32: QCT revenue mix
A33: Handsets % of QCT | B33: % | C33: =C9/C12 -> 0.79389766 | D33: =D9/D12 -> 0.76999751 | E33: =E9/E12 -> 0.73106953 | F33: =F9/F12 -> 0.70246601 | G33: =G9/G12 -> 0.75109084 | H33: =H9/H12 -> 0.73175626 | I33: =I9/I12 -> 0.7036584 | J33: =J9/J12 -> 0.70878729 | ... M33: =M9/M12 -> 0.5980715
A34: Automotive + IoT % of QCT | B34: % | C34: =(C10+C11)/C12 -> 0.20610234 | D34: =(D10+D11)/D12 -> 0.23000249 | E34: =(E10+E11)/E12 -> 0.26893047 | F34: =(F10+F11)/F12 -> 0.29753399 | G34: =(G10+G11)/G12 -> 0.24890916 | H34: =(H10+H11)/H12 -> 0.26824374 | I34: =(I10+I11)/I12 -> 0.2963416 | J34: =(J10+J11)/J12 -> 0.29121271 | ... M34: =(M10+M11)/M12 -> 0.4019285

Sheet Guidance
A1: Guidance
A2: Revenue guidance issued in the prior quarter's earnings release, $ in millions. FY24 Q1 guidance not collected (see docs/assumptions.md).
A4: Line item | B4: Unit | C4: FY24 Q1 | D4: FY24 Q2 | E4: FY24 Q3 | F4: FY24 Q4 | G4: FY25 Q1 | H4: FY25 Q2 | I4: FY25 Q3 | J4: FY25 Q4 | K4: FY26 Q1 | L4: FY26 Q2 | M4: FY26 Q3 | N4: FY26 Q4
A5: Issued (release date) | C5: n/a | D5: 2024-01-31 | E5: 2024-05-01 | F5: 2024-07-31 | G5: 2024-11-06 | H5: 2025-02-05 | I5: 2025-04-30 | J5: 2025-07-30 | K5: 2025-11-05 | L5: 2026-02-04 | M5: 2026-04-29 | N5: 2026-07-29
A6: Source ID | C6: n/a | D6: S1 | E6: S2 | F6: S3 | G6: S4 | H6: S5 | I6: S6 | J6: S7 | K6: S8 | L6: S9 | M6: S10 | N6: S11
A8: Total revenue (GAAP)
A9: Low | B9: $mm | C9: n/a | D9: 8900 | E9: 8800 | F9: 9500 | G9: 10500 | H9: 10300 | I9: 9900 | J9: 10300 | K9: 11800 | L9: 10200 | M9: 9200 | N9: 9700
A10: High | B10: $mm | C10: n/a | D10: 9700 | E10: 9600 | F10: 10300 | G10: 11300 | H10: 11200 | I10: 10700 | J10: 11100 | K10: 12600 | L10: 11000 | M10: 10000 | N10: 10500
A11: Midpoint | B11: $mm | C11: n/a | D11: =AVERAGE(D9:D10) -> 9300 | E11: =AVERAGE(E9:E10) -> 9200 | F11: =AVERAGE(F9:F10) -> 9900 | G11: =AVERAGE(G9:G10) -> 10900 | H11: =AVERAGE(H9:H10) -> 10750 | I11: =AVERAGE(I9:I10) -> 10300 | J11: =AVERAGE(J9:J10) -> 10700 | K11: =AVERAGE(K9:K10) -> 12200 | ... N11: =AVERAGE(N9:N10) -> 10100
A13: QCT revenue
A14: Low | B14: $mm | C14: n/a | D14: 7600 | E14: 7500 | F14: 8100 | G14: 9000 | H14: 8900 | I14: 8700 | J14: 9000 | K14: 10300 | L14: 8800 | M14: 7900 | N14: 8400
A15: High | B15: $mm | C15: n/a | D15: 8200 | E15: 8100 | F15: 8700 | G15: 9600 | H15: 9500 | I15: 9300 | J15: 9600 | K15: 10900 | L15: 9400 | M15: 8500 | N15: 9000
A16: Midpoint | B16: $mm | C16: n/a | D16: =AVERAGE(D14:D15) -> 7900 | E16: =AVERAGE(E14:E15) -> 7800 | F16: =AVERAGE(F14:F15) -> 8400 | G16: =AVERAGE(G14:G15) -> 9300 | H16: =AVERAGE(H14:H15) -> 9200 | I16: =AVERAGE(I14:I15) -> 9000 | J16: =AVERAGE(J14:J15) -> 9300 | K16: =AVERAGE(K14:K15) -> 10600 | ... N16: =AVERAGE(N14:N15) -> 8700
A18: QTL revenue
A19: Low | B19: $mm | C19: n/a | D19: 1200 | E19: 1200 | F19: 1350 | G19: 1450 | H19: 1250 | I19: 1150 | J19: 1250 | K19: 1400 | L19: 1200 | M19: 1150 | N19: 1200
A20: High | B20: $mm | C20: n/a | D20: 1400 | E20: 1400 | F20: 1550 | G20: 1650 | H20: 1450 | I20: 1350 | J20: 1450 | K20: 1600 | L20: 1400 | M20: 1350 | N20: 1400
A21: Midpoint | B21: $mm | C21: n/a | D21: =AVERAGE(D19:D20) -> 1300 | E21: =AVERAGE(E19:E20) -> 1300 | F21: =AVERAGE(F19:F20) -> 1450 | G21: =AVERAGE(G19:G20) -> 1550 | H21: =AVERAGE(H19:H20) -> 1350 | I21: =AVERAGE(I19:I20) -> 1250 | J21: =AVERAGE(J19:J20) -> 1350 | K21: =AVERAGE(K19:K20) -> 1500 | ... N21: =AVERAGE(N19:N20) -> 1300
A23: Note: FY25 Q2 GAAP guidance includes dispute-settlement revenue; Non-GAAP range was $10.2B-$11.0B (S5).

Sheet Variance
A1: Guidance vs. Actual Variance
A2: Actual revenue vs. guidance midpoint, $ in millions. Positive = beat.
A4: Line item | B4: Unit | C4: FY24 Q1 | D4: FY24 Q2 | E4: FY24 Q3 | F4: FY24 Q4 | G4: FY25 Q1 | H4: FY25 Q2 | I4: FY25 Q3 | J4: FY25 Q4 | K4: FY26 Q1 | L4: FY26 Q2 | M4: FY26 Q3
C5: n/a
A6: QCT revenue
A7: Actual | B7: $mm | D7: =Actuals!D12 -> 8026 | E7: =Actuals!E12 -> 8069 | F7: =Actuals!F12 -> 8678 | G7: =Actuals!G12 -> 10084 | H7: =Actuals!H12 -> 9469 | I7: =Actuals!I12 -> 8993 | J7: =Actuals!J12 -> 9821 | K7: =Actuals!K12 -> 10613 | ... M7: =Actuals!M12 -> 8504
A8: Guidance low | B8: $mm | D8: =Guidance!D14 -> 7600 | E8: =Guidance!E14 -> 7500 | F8: =Guidance!F14 -> 8100 | G8: =Guidance!G14 -> 9000 | H8: =Guidance!H14 -> 8900 | I8: =Guidance!I14 -> 8700 | J8: =Guidance!J14 -> 9000 | K8: =Guidance!K14 -> 10300 | ... M8: =Guidance!M14 -> 7900
A9: Guidance high | B9: $mm | D9: =Guidance!D15 -> 8200 | E9: =Guidance!E15 -> 8100 | F9: =Guidance!F15 -> 8700 | G9: =Guidance!G15 -> 9600 | H9: =Guidance!H15 -> 9500 | I9: =Guidance!I15 -> 9300 | J9: =Guidance!J15 -> 9600 | K9: =Guidance!K15 -> 10900 | ... M9: =Guidance!M15 -> 8500
A10: Guidance midpoint | B10: $mm | D10: =Guidance!D16 -> 7900 | E10: =Guidance!E16 -> 7800 | F10: =Guidance!F16 -> 8400 | G10: =Guidance!G16 -> 9300 | H10: =Guidance!H16 -> 9200 | I10: =Guidance!I16 -> 9000 | J10: =Guidance!J16 -> 9300 | K10: =Guidance!K16 -> 10600 | ... M10: =Guidance!M16 -> 8200
A11: Variance vs. midpoint ($mm) | B11: $mm | D11: =D7-D10 -> 126 | E11: =E7-E10 -> 269 | F11: =F7-F10 -> 278 | G11: =G7-G10 -> 784 | H11: =H7-H10 -> 269 | I11: =I7-I10 -> -7 | J11: =J7-J10 -> 521 | K11: =K7-K10 -> 13 | ... M11: =M7-M10 -> 304
A12: Variance vs. midpoint (%) | B12: % | D12: =IF(D10=0,0,D11/D10) -> 0.015949367 | E12: =IF(E10=0,0,E11/E10) -> 0.034487179 | F12: =IF(F10=0,0,F11/F10) -> 0.033095238 | G12: =IF(G10=0,0,G11/G10) -> 0.084301075 | H12: =IF(H10=0,0,H11/H10) -> 0.02923913 | I12: =IF(I10=0,0,I11/I10) -> -0.00077777778 | J12: =IF(J10=0,0,J11/J10) -> 0.056021505 | K12: =IF(K10=0,0,K11/K10) -> 0.0012264151 | ... M12: =IF(M10=0,0,M11/M10) -> 0.037073171
A13: Position in range | D13: =IF(D7>D9,"Above",IF(D7<D8,"Below","Within")) -> Within | E13: =IF(E7>E9,"Above",IF(E7<E8,"Below","Within")) -> Within | F13: =IF(F7>F9,"Above",IF(F7<F8,"Below","Within")) -> Within | G13: =IF(G7>G9,"Above",IF(G7<G8,"Below","Within")) -> Above | H13: =IF(H7>H9,"Above",IF(H7<H8,"Below","Within")) -> Within | I13: =IF(I7>I9,"Above",IF(I7<I8,"Below","Within")) -> Within | J13: =IF(J7>J9,"Above",IF(J7<J8,"Below","Within")) -> Above | K13: =IF(K7>K9,"Above",IF(K7<K8,"Below","Within")) -> Within | ... M13: =IF(M7>M9,"Above",IF(M7<M8,"Below","Within")) -> Above
A14: Position (0% = low end, 100% = high end) | B14: % | D14: =IF(D9=D8,0,(D7-D8)/(D9-D8)) -> 0.71 | E14: =IF(E9=E8,0,(E7-E8)/(E9-E8)) -> 0.94833333 | F14: =IF(F9=F8,0,(F7-F8)/(F9-F8)) -> 0.96333333 | G14: =IF(G9=G8,0,(G7-G8)/(G9-G8)) -> 1.8066667 | H14: =IF(H9=H8,0,(H7-H8)/(H9-H8)) -> 0.94833333 | I14: =IF(I9=I8,0,(I7-I8)/(I9-I8)) -> 0.48833333 | J14: =IF(J9=J8,0,(J7-J8)/(J9-J8)) -> 1.3683333 | K14: =IF(K9=K8,0,(K7-K8)/(K9-K8)) -> 0.52166667 | ... M14: =IF(M9=M8,0,(M7-M8)/(M9-M8)) -> 1.0066667
A16: QTL revenue
A17: Actual | B17: $mm | D17: =Actuals!D13 -> 1318 | E17: =Actuals!E13 -> 1273 | F17: =Actuals!F13 -> 1521 | G17: =Actuals!G13 -> 1535 | H17: =Actuals!H13 -> 1319 | I17: =Actuals!I13 -> 1318 | J17: =Actuals!J13 -> 1409 | K17: =Actuals!K13 -> 1592 | ... M17: =Actuals!M13 -> 1278
A18: Guidance low | B18: $mm | D18: =Guidance!D19 -> 1200 | E18: =Guidance!E19 -> 1200 | F18: =Guidance!F19 -> 1350 | G18: =Guidance!G19 -> 1450 | H18: =Guidance!H19 -> 1250 | I18: =Guidance!I19 -> 1150 | J18: =Guidance!J19 -> 1250 | K18: =Guidance!K19 -> 1400 | ... M18: =Guidance!M19 -> 1150
A19: Guidance high | B19: $mm | D19: =Guidance!D20 -> 1400 | E19: =Guidance!E20 -> 1400 | F19: =Guidance!F20 -> 1550 | G19: =Guidance!G20 -> 1650 | H19: =Guidance!H20 -> 1450 | I19: =Guidance!I20 -> 1350 | J19: =Guidance!J20 -> 1450 | K19: =Guidance!K20 -> 1600 | ... M19: =Guidance!M20 -> 1350
A20: Guidance midpoint | B20: $mm | D20: =Guidance!D21 -> 1300 | E20: =Guidance!E21 -> 1300 | F20: =Guidance!F21 -> 1450 | G20: =Guidance!G21 -> 1550 | H20: =Guidance!H21 -> 1350 | I20: =Guidance!I21 -> 1250 | J20: =Guidance!J21 -> 1350 | K20: =Guidance!K21 -> 1500 | ... M20: =Guidance!M21 -> 1250
A21: Variance vs. midpoint ($mm) | B21: $mm | D21: =D17-D20 -> 18 | E21: =E17-E20 -> -27 | F21: =F17-F20 -> 71 | G21: =G17-G20 -> -15 | H21: =H17-H20 -> -31 | I21: =I17-I20 -> 68 | J21: =J17-J20 -> 59 | K21: =K17-K20 -> 92 | ... M21: =M17-M20 -> 28
A22: Variance vs. midpoint (%) | B22: % | D22: =IF(D20=0,0,D21/D20) -> 0.013846154 | E22: =IF(E20=0,0,E21/E20) -> -0.020769231 | F22: =IF(F20=0,0,F21/F20) -> 0.048965517 | G22: =IF(G20=0,0,G21/G20) -> -0.0096774194 | H22: =IF(H20=0,0,H21/H20) -> -0.022962963 | I22: =IF(I20=0,0,I21/I20) -> 0.0544 | J22: =IF(J20=0,0,J21/J20) -> 0.043703704 | K22: =IF(K20=0,0,K21/K20) -> 0.061333333 | ... M22: =IF(M20=0,0,M21/M20) -> 0.0224
A23: Position in range | D23: =IF(D17>D19,"Above",IF(D17<D18,"Below","Within")) -> Within | E23: =IF(E17>E19,"Above",IF(E17<E18,"Below","Within")) -> Within | F23: =IF(F17>F19,"Above",IF(F17<F18,"Below","Within")) -> Within | G23: =IF(G17>G19,"Above",IF(G17<G18,"Below","Within")) -> Within | H23: =IF(H17>H19,"Above",IF(H17<H18,"Below","Within")) -> Within | I23: =IF(I17>I19,"Above",IF(I17<I18,"Below","Within")) -> Within | J23: =IF(J17>J19,"Above",IF(J17<J18,"Below","Within")) -> Within | K23: =IF(K17>K19,"Above",IF(K17<K18,"Below","Within")) -> Within | ... M23: =IF(M17>M19,"Above",IF(M17<M18,"Below","Within")) -> Within
A24: Position (0% = low end, 100% = high end) | B24: % | D24: =IF(D19=D18,0,(D17-D18)/(D19-D18)) -> 0.59 | E24: =IF(E19=E18,0,(E17-E18)/(E19-E18)) -> 0.365 | F24: =IF(F19=F18,0,(F17-F18)/(F19-F18)) -> 0.855 | G24: =IF(G19=G18,0,(G17-G18)/(G19-G18)) -> 0.425 | H24: =IF(H19=H18,0,(H17-H18)/(H19-H18)) -> 0.345 | I24: =IF(I19=I18,0,(I17-I18)/(I19-I18)) -> 0.84 | J24: =IF(J19=J18,0,(J17-J18)/(J19-J18)) -> 0.795 | K24: =IF(K19=K18,0,(K17-K18)/(K19-K18)) -> 0.96 | ... M24: =IF(M19=M18,0,(M17-M18)/(M19-M18)) -> 0.64
A26: Scorecard (FY24 Q2 - FY26 Q3)
A27: Metric | B27: QCT | C27: QTL
A28: Quarters above guidance range | B28: =COUNTIF(D13:M13,"Above") -> 3 | C28: =COUNTIF(D23:M23,"Above") -> 0
A29: Quarters within guidance range | B29: =COUNTIF(D13:M13,"Within") -> 7 | C29: =COUNTIF(D23:M23,"Within") -> 10
A30: Quarters below guidance range | B30: =COUNTIF(D13:M13,"Below") -> 0 | C30: =COUNTIF(D23:M23,"Below") -> 0
A31: Average variance vs. midpoint (%) | B31: =AVERAGE(D12:M12) -> 0.028797794 | C31: =AVERAGE(D22:M22) -> 0.025431602
A32: Average position in range | B32: =AVERAGE(D14:M14) -> 0.92216667 | C32: =AVERAGE(D24:M24) -> 0.6725
A33: Largest beat vs. midpoint ($mm) | B33: =MAX(D11:M11) -> 784 | C33: =MAX(D21:M21) -> 92
A34: Largest miss vs. midpoint ($mm) | B34: =MIN(D11:M11) -> -24 | C34: =MIN(D21:M21) -> -31

Sheet Forecast
A1: Quarterly Forecast
A2: Actuals FY24 Q1 - FY26 Q3 (linked) + forecast FY26 Q4 - FY27 Q4 (grey). $ in millions.
A4: Line item | B4: Unit | C4: FY24 Q1 | D4: FY24 Q2 | E4: FY24 Q3 | F4: FY24 Q4 | G4: FY25 Q1 | H4: FY25 Q2 | I4: FY25 Q3 | J4: FY25 Q4 | K4: FY26 Q1 | L4: FY26 Q2 | M4: FY26 Q3 | N4: FY26 Q4 | O4: FY27 Q1 | P4: FY27 Q2 | Q4: FY27 Q3 | R4: FY27 Q4
A5: Type | C5: Actual | D5: Actual | E5: Actual | F5: Actual | G5: Actual | H5: Actual | I5: Actual | J5: Actual | K5: Actual | L5: Actual | M5: Actual | N5: Forecast | O5: Forecast | P5: Forecast | Q5: Forecast | R5: Forecast
A6: Scenario | C6: Reported | D6: Reported | E6: Reported | F6: Reported | G6: Reported | H6: Reported | I6: Reported | J6: Reported | K6: Reported | L6: Reported | M6: Reported | N6: =Assumptions!$C$5 -> Base | O6: =Assumptions!$C$5 -> Base | P6: =Assumptions!$C$5 -> Base | Q6: =Assumptions!$C$5 -> Base | R6: =Assumptions!$C$5 -> Base
A8: Revenue ($mm)
A9: Handsets | B9: $mm | C9: =Actuals!C9 -> 6687 | D9: =Actuals!D9 -> 6180 | E9: =Actuals!E9 -> 5899 | F9: =Actuals!F9 -> 6096 | G9: =Actuals!G9 -> 7574 | H9: =Actuals!H9 -> 6929 | I9: =Actuals!I9 -> 6328 | J9: =Actuals!J9 -> 6961 | ... M9: =Actuals!M9 -> 5086 | N9: =J9*(1+Assumptions!$F$8) -> 5081.53 | O9: =K9*(1+Assumptions!$F$9) -> 6885.12 | P9: =L9*(1+Assumptions!$F$9) -> 5301.12 | Q9: =M9*(1+Assumptions!$F$9) -> 4475.68 | R9: =N9*(1+Assumptions!$F$9) -> 4471.7464
A10: Automotive | B10: $mm | C10: =Actuals!C10 -> 598 | D10: =Actuals!D10 -> 603 | E10: =Actuals!E10 -> 811 | F10: =Actuals!F10 -> 899 | G10: =Actuals!G10 -> 961 | H10: =Actuals!H10 -> 959 | I10: =Actuals!I10 -> 984 | J10: =Actuals!J10 -> 1053 | ... M10: =Actuals!M10 -> 1588 | N10: =J10*(1+Assumptions!$F$10) -> 1684.8 | O10: =K10*(1+Assumptions!$F$11) -> 1431.3 | P10: =L10*(1+Assumptions!$F$11) -> 1723.8 | Q10: =M10*(1+Assumptions!$F$11) -> 2064.4 | R10: =N10*(1+Assumptions!$F$11) -> 2190.24
A11: IoT | B11: $mm | C11: =Actuals!C11 -> 1138 | D11: =Actuals!D11 -> 1243 | E11: =Actuals!E11 -> 1359 | F11: =Actuals!F11 -> 1683 | G11: =Actuals!G11 -> 1549 | H11: =Actuals!H11 -> 1581 | I11: =Actuals!I11 -> 1681 | J11: =Actuals!J11 -> 1807 | ... M11: =Actuals!M11 -> 1830 | N11: =J11*(1+Assumptions!$F$12) -> 1969.63 | O11: =K11*(1+Assumptions!$F$13) -> 1856.8 | P11: =L11*(1+Assumptions!$F$13) -> 1898.6 | Q11: =M11*(1+Assumptions!$F$13) -> 2013 | R11: =N11*(1+Assumptions!$F$13) -> 2166.593
A12: QCT revenue | B12: $mm | C12: =Actuals!C12 -> 8423 | D12: =Actuals!D12 -> 8026 | E12: =Actuals!E12 -> 8069 | F12: =Actuals!F12 -> 8678 | G12: =Actuals!G12 -> 10084 | H12: =Actuals!H12 -> 9469 | I12: =Actuals!I12 -> 8993 | J12: =Actuals!J12 -> 9821 | ... M12: =Actuals!M12 -> 8504 | N12: =SUM(N9:N11) -> 8735.96 | O12: =SUM(O9:O11) -> 10173.22 | P12: =SUM(P9:P11) -> 8923.52 | Q12: =SUM(Q9:Q11) -> 8553.08 | R12: =SUM(R9:R11) -> 8828.5794
A13: QTL revenue | B13: $mm | C13: =Actuals!C13 -> 1460 | D13: =Actuals!D13 -> 1318 | E13: =Actuals!E13 -> 1273 | F13: =Actuals!F13 -> 1521 | G13: =Actuals!G13 -> 1535 | H13: =Actuals!H13 -> 1319 | I13: =Actuals!I13 -> 1318 | J13: =Actuals!J13 -> 1409 | ... M13: =Actuals!M13 -> 1278 | N13: =J13*(1+Assumptions!$F$14) -> 1296.28 | O13: =K13*(1+Assumptions!$F$15) -> 1544.24 | P13: =L13*(1+Assumptions!$F$15) -> 1340.54 | Q13: =M13*(1+Assumptions!$F$15) -> 1239.66 | R13: =N13*(1+Assumptions!$F$15) -> 1257.3916
A14: QCT + QTL revenue | B14: $mm | C14: =C12+C13 -> 9883 | D14: =D12+D13 -> 9344 | E14: =E12+E13 -> 9342 | F14: =F12+F13 -> 10199 | G14: =G12+G13 -> 11619 | H14: =H12+H13 -> 10788 | I14: =I12+I13 -> 10311 | J14: =J12+J13 -> 11230 | ... R14: =R12+R13 -> 10085.971
A16: Earnings before taxes ($mm)
A17: QCT EBT | B17: $mm | C17: =Actuals!C17 -> 2593 | D17: =Actuals!D17 -> 2288 | E17: =Actuals!E17 -> 2181 | F17: =Actuals!F17 -> 2465 | G17: =Actuals!G17 -> 3246 | H17: =Actuals!H17 -> 2857 | I17: =Actuals!I17 -> 2671 | J17: =Actuals!J17 -> 2896 | ... M17: =Actuals!M17 -> 2192 | N17: =N12*Assumptions!$F$16 -> 2096.6304 | O17: =O12*Assumptions!$F$17 -> 2645.0372 | P17: =P12*Assumptions!$F$17 -> 2320.1152 | Q17: =Q12*Assumptions!$F$17 -> 2223.8008 | R17: =R12*Assumptions!$F$17 -> 2295.4306
A18: QTL EBT | B18: $mm | C18: =Actuals!C18 -> 1080 | D18: =Actuals!D18 -> 933 | E18: =Actuals!E18 -> 894 | F18: =Actuals!F18 -> 1120 | G18: =Actuals!G18 -> 1158 | H18: =Actuals!H18 -> 929 | I18: =Actuals!I18 -> 942 | J18: =Actuals!J18 -> 1015 | ... M18: =Actuals!M18 -> 881 | N18: =N13*Assumptions!$F$18 -> 907.396 | O18: =O13*Assumptions!$F$19 -> 1080.968 | P18: =P13*Assumptions!$F$19 -> 938.378 | Q18: =Q13*Assumptions!$F$19 -> 867.762 | R18: =R13*Assumptions!$F$19 -> 880.17412
A19: QCT + QTL EBT | B19: $mm | C19: =C17+C18 -> 3673 | D19: =D17+D18 -> 3221 | E19: =E17+E18 -> 3075 | F19: =F17+F18 -> 3585 | G19: =G17+G18 -> 4404 | H19: =H17+H18 -> 3786 | I19: =I17+I18 -> 3613 | J19: =J17+J18 -> 3911 | ... R19: =R17+R18 -> 3175.6048
A21: Margins
A22: QCT EBT margin | B22: % | C22: =IF(C12=0,0,C17/C12) -> 0.30784756 | D22: =IF(D12=0,0,D17/D12) -> 0.28507351 | E22: =IF(E12=0,0,E17/E12) -> 0.27029372 | F22: =IF(F12=0,0,F17/F12) -> 0.28405162 | G22: =IF(G12=0,0,G17/G12) -> 0.32189607 | H22: =IF(H12=0,0,H17/H12) -> 0.30172141 | I22: =IF(I12=0,0,I17/I12) -> 0.29700878 | J22: =IF(J12=0,0,J17/J12) -> 0.29487832 | ... R22: =IF(R12=0,0,R17/R12) -> 0.26
A23: QTL EBT margin | B23: % | C23: =IF(C13=0,0,C18/C13) -> 0.73972603 | D23: =IF(D13=0,0,D18/D13) -> 0.70789074 | E23: =IF(E13=0,0,E18/E13) -> 0.70227808 | F23: =IF(F13=0,0,F18/F13) -> 0.73635766 | G23: =IF(G13=0,0,G18/G13) -> 0.75439739 | H23: =IF(H13=0,0,H18/H13) -> 0.70432146 | I23: =IF(I13=0,0,I18/I13) -> 0.71471927 | J23: =IF(J13=0,0,J18/J13) -> 0.72036906 | ... R23: =IF(R13=0,0,R18/R13) -> 0.7
A25: Diversification metrics
A26: QCT + QTL revenue, YoY growth | B26: % | C26: n/a | D26: n/a | E26: n/a | F26: n/a | G26: =IF(C14=0,0,G14/C14-1) -> 0.17565517 | H26: =IF(D14=0,0,H14/D14-1) -> 0.15453767 | I26: =IF(E14=0,0,I14/E14-1) -> 0.10372511 | J26: =IF(F14=0,0,J14/F14-1) -> 0.10108834 | K26: =IF(G14=0,0,K14/G14-1) -> 0.050434633 | L26: =IF(H14=0,0,L14/H14-1) -> -0.030589544 | M26: =IF(I14=0,0,M14/I14-1) -> -0.051304432 | N26: =IF(J14=0,0,N14/J14-1) -> -0.10665717 | ... R26: =IF(N14=0,0,R14/N14-1) -> 0.0053558328
A27: Non-handset QCT revenue (Auto + IoT) | B27: $mm | C27: =C10+C11 -> 1736 | D27: =D10+D11 -> 1846 | E27: =E10+E11 -> 2170 | F27: =F10+F11 -> 2582 | G27: =G10+G11 -> 2510 | H27: =H10+H11 -> 2540 | I27: =I10+I11 -> 2665 | J27: =J10+J11 -> 2860 | ... R27: =R10+R11 -> 4356.833
A28: Non-handset share of QCT | B28: % | C28: =IF(C12=0,0,C27/C12) -> 0.20610234 | D28: =IF(D12=0,0,D27/D12) -> 0.23000249 | E28: =IF(E12=0,0,E27/E12) -> 0.26893047 | F28: =IF(F12=0,0,F27/F12) -> 0.29753399 | G28: =IF(G12=0,0,G27/G12) -> 0.24890916 | H28: =IF(H12=0,0,H27/H12) -> 0.26824374 | I28: =IF(I12=0,0,I27/I12) -> 0.2963416 | J28: =IF(J12=0,0,J27/J12) -> 0.29121271 | ... R28: =IF(R12=0,0,R27/R12) -> 0.49349197
A29: Non-handset QCT revenue, YoY growth | B29: % | C29: n/a | D29: n/a | E29: n/a | F29: n/a | G29: =IF(C27=0,0,G27/C27-1) -> 0.44585253 | H29: =IF(D27=0,0,H27/D27-1) -> 0.375948 | I29: =IF(E27=0,0,I27/E27-1) -> 0.2281106 | J29: =IF(F27=0,0,J27/F27-1) -> 0.10766847 | K29: =IF(G27=0,0,K27/G27-1) -> 0.11115538 | L29: =IF(H27=0,0,L27/H27-1) -> 0.2015748 | M29: =IF(I27=0,0,M27/I27-1) -> 0.28255159 | N29: =IF(J27=0,0,N27/J27-1) -> 0.27777273 | ... R29: =IF(N27=0,0,R27/N27-1) -> 0.1922059
A30: Handsets, YoY growth | B30: % | C30: n/a | D30: n/a | E30: n/a | F30: n/a | G30: =IF(C9=0,0,G9/C9-1) -> 0.13264543 | H30: =IF(D9=0,0,H9/D9-1) -> 0.12119741 | I30: =IF(E9=0,0,I9/E9-1) -> 0.072724191 | J30: =IF(F9=0,0,J9/F9-1) -> 0.14189633 | K30: =IF(G9=0,0,K9/G9-1) -> 0.033007658 | L30: =IF(H9=0,0,L9/H9-1) -> -0.13061048 | M30: =IF(I9=0,0,M9/I9-1) -> -0.19627054 | N30: =IF(J9=0,0,N9/J9-1) -> -0.27 | ... R30: =IF(N9=0,0,R9/N9-1) -> -0.12
A32: Method: forecast quarter = same quarter prior year x (1 + YoY growth from Assumptions). QCT forecast = sum of streams; EBT = revenue x EBT margin.

Sheet Summary
A1: Fiscal Year Summary
A2: Fiscal years end late September. FY26E = 3 reported quarters + Q4 forecast. $ in millions.
A4: Line item | B4: Unit | C4: FY24 | D4: FY25 | E4: FY26E | F4: FY27E
A5: Basis | C5: Actual | D5: Actual | E5: Act + Fcst | F5: Forecast
A6: Scenario | C6: =Assumptions!$C$5 -> Base
A7: Revenue and EBT ($mm)
A8: Handsets | B8: $mm | C8: =SUM(Forecast!C9:F9) -> 24862 | D8: =SUM(Forecast!G9:J9) -> 27792 | E8: =SUM(Forecast!K9:N9) -> 24015.53 | F8: =SUM(Forecast!O9:R9) -> 21133.666
A9: Automotive | B9: $mm | C9: =SUM(Forecast!C10:F10) -> 2911 | D9: =SUM(Forecast!G10:J10) -> 3957 | E9: =SUM(Forecast!K10:N10) -> 5699.8 | F9: =SUM(Forecast!O10:R10) -> 7409.74
A10: IoT | B10: $mm | C10: =SUM(Forecast!C11:F11) -> 5423 | D10: =SUM(Forecast!G11:J11) -> 6618 | E10: =SUM(Forecast!K11:N11) -> 7213.63 | F10: =SUM(Forecast!O11:R11) -> 7934.993
A11: QCT revenue | B11: $mm | C11: =SUM(Forecast!C12:F12) -> 33196 | D11: =SUM(Forecast!G12:J12) -> 38367 | E11: =SUM(Forecast!K12:N12) -> 36928.96 | F11: =SUM(Forecast!O12:R12) -> 36478.399
A12: QTL revenue | B12: $mm | C12: =SUM(Forecast!C13:F13) -> 5572 | D12: =SUM(Forecast!G13:J13) -> 5581 | E12: =SUM(Forecast!K13:N13) -> 5548.28 | F12: =SUM(Forecast!O13:R13) -> 5381.8316
A13: QCT + QTL revenue | B13: $mm | C13: =SUM(Forecast!C14:F14) -> 38768 | D13: =SUM(Forecast!G14:J14) -> 43948 | E13: =SUM(Forecast!K14:N14) -> 42477.24 | F13: =SUM(Forecast!O14:R14) -> 41860.231
A15: QCT EBT | B15: $mm | C15: =SUM(Forecast!C17:F17) -> 9527 | D15: =SUM(Forecast!G17:J17) -> 11670 | E15: =SUM(Forecast!K17:N17) -> 10055.63 | F15: =SUM(Forecast!O17:R17) -> 9484.3838
A16: QTL EBT | B16: $mm | C16: =SUM(Forecast!C18:F18) -> 4027 | D16: =SUM(Forecast!G18:J18) -> 4044 | E16: =SUM(Forecast!K18:N18) -> 4013.396 | F16: =SUM(Forecast!O18:R18) -> 3767.2821
A17: QCT + QTL EBT | B17: $mm | C17: =SUM(Forecast!C19:F19) -> 13554 | D17: =SUM(Forecast!G19:J19) -> 15714 | E17: =SUM(Forecast!K19:N19) -> 14069.026 | F17: =SUM(Forecast!O19:R19) -> 13251.666
A19: Growth and margins
A20: Handsets, YoY | B20: % | C20: n/a | D20: =IF(C8=0,0,D8/C8-1) -> 0.11785053 | E20: =IF(D8=0,0,E8/D8-1) -> -0.13588335 | F20: =IF(E8=0,0,F8/E8-1) -> -0.12
A21: Automotive, YoY | B21: % | C21: n/a | D21: =IF(C9=0,0,D9/C9-1) -> 0.35932669 | E21: =IF(D9=0,0,E9/D9-1) -> 0.44043467 | F21: =IF(E9=0,0,F9/E9-1) -> 0.3
A22: IoT, YoY | B22: % | C22: n/a | D22: =IF(C10=0,0,D10/C10-1) -> 0.22035774 | E22: =IF(D10=0,0,E10/D10-1) -> 0.090001511 | F22: =IF(E10=0,0,F10/E10-1) -> 0.1
A23: QCT revenue, YoY | B23: % | C23: n/a | D23: =IF(C11=0,0,D11/C11-1) -> 0.15577178 | E23: =IF(D11=0,0,E11/D11-1) -> -0.037481169 | F23: =IF(E11=0,0,F11/E11-1) -> -0.012200739
A24: QTL revenue, YoY | B24: % | C24: n/a | D24: =IF(C12=0,0,D12/C12-1) -> 0.001615219 | E24: =IF(D12=0,0,E12/D12-1) -> -0.0058627486 | F24: =IF(E12=0,0,F12/E12-1) -> -0.03
A25: QCT + QTL revenue, YoY | B25: % | C25: n/a | D25: =IF(C13=0,0,D13/C13-1) -> 0.13361535 | E25: =IF(D13=0,0,E13/D13-1) -> -0.033465914 | F25: =IF(E13=0,0,F13/E13-1) -> -0.014525638
A26: QCT EBT margin | B26: % | C26: =IF(C11=0,0,C15/C11) -> 0.28699241 | D26: =IF(D11=0,0,D15/D11) -> 0.30416764 | E26: =IF(E11=0,0,E15/E11) -> 0.2722966 | F26: =IF(F11=0,0,F15/F11) -> 0.26
A27: QTL EBT margin | B27: % | C27: =IF(C12=0,0,C16/C12) -> 0.72272075 | D27: =IF(D12=0,0,D16/D12) -> 0.72460133 | E27: =IF(E12=0,0,E16/E12) -> 0.72335859 | F27: =IF(F12=0,0,F16/F12) -> 0.7
A29: Core question: does diversification offset handset decline?
A30: Change in handset revenue vs. prior year | B30: $mm | C30: n/a | D30: =D8-C8 -> 2930 | E30: =E8-D8 -> -3776.47 | F30: =F8-E8 -> -2881.8636
A31: Change in Auto + IoT revenue vs. prior year | B31: $mm | C31: n/a | D31: =(D9+D10)-(C9+C10) -> 2241 | E31: =(E9+E10)-(D9+D10) -> 2338.43 | F31: =(F9+F10)-(E9+E10) -> 2431.303
A32: Change in QTL revenue vs. prior year | B32: $mm | C32: n/a | D32: =D12-C12 -> 9 | E32: =E12-D12 -> -32.72 | F32: =F12-E12 -> -166.4484
A33: Net change in QCT + QTL revenue | B33: $mm | C33: n/a | D33: =SUM(D30:D32) -> 5180 | E33: =SUM(E30:E32) -> -1470.76 | F33: =SUM(F30:F32) -> -617.009
A34: Offset ratio (Auto + IoT gain / handset loss) | B34: x | C34: n/a | D34: =IF(D30>=0,"No decline",D31/-D30) -> No decline | E34: =IF(E30>=0,"No decline",E31/-E30) -> 0.61921053 | F34: =IF(F30>=0,"No decline",F31/-F30) -> 0.84365651
A35: Non-handset share of QCT revenue | B35: % | C35: =IF(C11=0,0,(C9+C10)/C11) -> 0.25105434 | D35: =IF(D11=0,0,(D9+D10)/D11) -> 0.27562749 | E35: =IF(E11=0,0,(E9+E10)/E11) -> 0.34968301 | F35: =IF(F11=0,0,(F9+F10)/F11) -> 0.42065258
A36: Verdict | C36: n/a | D36: =IF(D30>=0,"Handsets grew",IF(D31>=-D30,"Offset","Not offset")) -> Handsets grew | E36: =IF(E30>=0,"Handsets grew",IF(E31>=-E30,"Offset","Not offset")) -> Not offset | F36: =IF(F30>=0,"Handsets grew",IF(F31>=-F30,"Offset","Not offset")) -> Not offset
A38: Offset ratio >= 1.00x means Automotive + IoT added at least as many dollars as Handsets lost that year.

Sheet Scenarios
A1: Scenario Comparison
A2: Computed directly from each scenario's drivers, so all three show at once regardless of the selector. $ in millions.
A4: Line item | B4: Unit | C4: Base | D4: Bull | E4: Bear
A5: FY26E revenue ($mm)
A6: Handsets | B6: $mm | C6: =SUM(Forecast!K9:M9)+Forecast!J9*(1+Assumptions!$C$8) -> 24015.53 | D6: =SUM(Forecast!K9:M9)+Forecast!J9*(1+Assumptions!$D$8) -> 24363.58 | E6: =SUM(Forecast!K9:M9)+Forecast!J9*(1+Assumptions!$E$8) -> 23667.48
A7: Automotive | B7: $mm | C7: =SUM(Forecast!K10:M10)+Forecast!J10*(1+Assumptions!$C$10) -> 5699.8 | D7: =SUM(Forecast!K10:M10)+Forecast!J10*(1+Assumptions!$D$10) -> 5752.45 | E7: =SUM(Forecast!K10:M10)+Forecast!J10*(1+Assumptions!$E$10) -> 5594.5
A8: IoT | B8: $mm | C8: =SUM(Forecast!K11:M11)+Forecast!J11*(1+Assumptions!$C$12) -> 7213.63 | D8: =SUM(Forecast!K11:M11)+Forecast!J11*(1+Assumptions!$D$12) -> 7267.84 | E8: =SUM(Forecast!K11:M11)+Forecast!J11*(1+Assumptions!$E$12) -> 7141.35
A9: QTL revenue | B9: $mm | C9: =SUM(Forecast!K13:M13)+Forecast!J13*(1+Assumptions!$C$14) -> 5548.28 | D9: =SUM(Forecast!K13:M13)+Forecast!J13*(1+Assumptions!$D$14) -> 5646.91 | E9: =SUM(Forecast!K13:M13)+Forecast!J13*(1+Assumptions!$E$14) -> 5463.74
A10: QCT + QTL revenue | B10: $mm | C10: =SUM(C6:C9) -> 42477.24 | D10: =SUM(D6:D9) -> 43030.78 | E10: =SUM(E6:E9) -> 41867.07
A12: FY27E revenue ($mm)
A13: Handsets | B13: $mm | C13: =(SUM(Forecast!K9:M9)+Forecast!J9*(1+Assumptions!$C$8))*(1+Assumptions!$C$9) -> 21133.666 | D13: =(SUM(Forecast!K9:M9)+Forecast!J9*(1+Assumptions!$D$8))*(1+Assumptions!$D$9) -> 23145.401 | E13: =(SUM(Forecast!K9:M9)+Forecast!J9*(1+Assumptions!$E$8))*(1+Assumptions!$E$9) -> 18933.984
A14: Automotive | B14: $mm | C14: =(SUM(Forecast!K10:M10)+Forecast!J10*(1+Assumptions!$C$10))*(1+Assumptions!$C$11) -> 7409.74 | D14: =(SUM(Forecast!K10:M10)+Forecast!J10*(1+Assumptions!$D$10))*(1+Assumptions!$D$11) -> 8053.43 | E14: =(SUM(Forecast!K10:M10)+Forecast!J10*(1+Assumptions!$E$10))*(1+Assumptions!$E$11) -> 6713.4
A15: IoT | B15: $mm | C15: =(SUM(Forecast!K11:M11)+Forecast!J11*(1+Assumptions!$C$12))*(1+Assumptions!$C$13) -> 7934.993 | D15: =(SUM(Forecast!K11:M11)+Forecast!J11*(1+Assumptions!$D$12))*(1+Assumptions!$D$13) -> 8358.016 | E15: =(SUM(Forecast!K11:M11)+Forecast!J11*(1+Assumptions!$E$12))*(1+Assumptions!$E$13) -> 7498.4175
A16: QTL revenue | B16: $mm | C16: =(SUM(Forecast!K13:M13)+Forecast!J13*(1+Assumptions!$C$14))*(1+Assumptions!$C$15) -> 5381.8316 | D16: =(SUM(Forecast!K13:M13)+Forecast!J13*(1+Assumptions!$D$14))*(1+Assumptions!$D$15) -> 5703.3791 | E16: =(SUM(Forecast!K13:M13)+Forecast!J13*(1+Assumptions!$E$14))*(1+Assumptions!$E$15) -> 5081.2782
A17: QCT + QTL revenue | B17: $mm | C17: =SUM(C13:C16) -> 41860.231 | D17: =SUM(D13:D16) -> 45260.226 | E17: =SUM(E13:E16) -> 38227.08
A19: FY27E profitability and growth
A20: QCT revenue | B20: $mm | C20: =C13+C14+C15 -> 36478.399 | D20: =D13+D14+D15 -> 39556.847 | E20: =E13+E14+E15 -> 33145.802
A21: QCT EBT | B21: $mm | C21: =C20*Assumptions!$C$17 -> 9484.3838 | D21: =D20*Assumptions!$D$17 -> 11471.486 | E21: =E20*Assumptions!$E$17 -> 7623.5343
A22: QTL EBT | B22: $mm | C22: =C16*Assumptions!$C$19 -> 3767.2821 | D22: =D16*Assumptions!$D$19 -> 4163.4667 | E22: =E16*Assumptions!$E$19 -> 3404.4564
A23: QCT + QTL EBT | B23: $mm | C23: =C21+C22 -> 13251.666 | D23: =D21+D22 -> 15634.952 | E23: =E21+E22 -> 11027.991
A24: QCT + QTL revenue, YoY vs. FY26E | B24: % | C24: =IF(C10=0,0,C17/C10-1) -> -0.014525638 | D24: =IF(D10=0,0,D17/D10-1) -> 0.051810497 | E24: =IF(E10=0,0,E17/E10-1) -> -0.086941606
A25: Non-handset share of QCT, FY27E | B25: % | C25: =IF(C20=0,0,(C14+C15)/C20) -> 0.42065258 | D25: =IF(D20=0,0,(D14+D15)/D20) -> 0.41488256 | E25: =IF(E20=0,0,(E14+E15)/E20) -> 0.42876675
A26: Handsets $ change, FY27E vs. FY26E | B26: $mm | C26: =C13-C6 -> -2881.8636 | D26: =D13-D6 -> -1218.179 | E26: =E13-E6 -> -4733.496
A27: Auto + IoT $ change, FY27E vs. FY26E | B27: $mm | C27: =(C14+C15)-(C7+C8) -> 2431.303 | D27: =(D14+D15)-(D7+D8) -> 3391.156 | E27: =(E14+E15)-(E7+E8) -> 1475.9675
A28: Verdict | C28: =IF(C26>=0,"Handsets grew",IF(C27>=-C26,"Offset","Not offset")) -> Not offset | D28: =IF(D26>=0,"Handsets grew",IF(D27>=-D26,"Offset","Not offset")) -> Offset | E28: =IF(E26>=0,"Handsets grew",IF(E27>=-E26,"Offset","Not offset")) -> Not offset
A30: Tie-out: the column matching the active scenario equals Summary FY26E / FY27E (see Checks).

Sheet Sensitivity
A1: Sensitivity: FY27E Revenue
A2: QCT + QTL revenue ($mm) for FY27E by handset growth (rows) x automotive growth (columns). IoT and QTL use the active scenario.
A4: FY26E bases (active scenario)
A5: Handsets | B5: =Summary!E8 -> 24015.53
A6: Automotive | B6: =Summary!E9 -> 5699.8
A7: IoT | B7: =Summary!E10 -> 7213.63
A8: QTL revenue | B8: =Summary!E12 -> 5548.28
A9: IoT FY27 growth (active) | B9: =Assumptions!$F$13 -> 0.1
A10: QTL FY27 growth (active) | B10: =Assumptions!$F$15 -> -0.03
A12: Handsets YoY \ Automotive YoY | C12: 0.1 | D12: 0.2 | E12: 0.3 | F12: 0.4 | G12: 0.5
B13: -0.25 | C13: =$B$5*(1+$B13)+$B$6*(1+C$12)+$B$7*(1+$B$9)+$B$8*(1+$B$10) -> 37598.252 | D13: =$B$5*(1+$B13)+$B$6*(1+D$12)+$B$7*(1+$B$9)+$B$8*(1+$B$10) -> 38168.232 | E13: =$B$5*(1+$B13)+$B$6*(1+E$12)+$B$7*(1+$B$9)+$B$8*(1+$B$10) -> 38738.212 | F13: =$B$5*(1+$B13)+$B$6*(1+F$12)+$B$7*(1+$B$9)+$B$8*(1+$B$10) -> 39308.192 | G13: =$B$5*(1+$B13)+$B$6*(1+G$12)+$B$7*(1+$B$9)+$B$8*(1+$B$10) -> 39878.172
B14: -0.2 | C14: =$B$5*(1+$B14)+$B$6*(1+C$12)+$B$7*(1+$B$9)+$B$8*(1+$B$10) -> 38799.029 | D14: =$B$5*(1+$B14)+$B$6*(1+D$12)+$B$7*(1+$B$9)+$B$8*(1+$B$10) -> 39369.009 | E14: =$B$5*(1+$B14)+$B$6*(1+E$12)+$B$7*(1+$B$9)+$B$8*(1+$B$10) -> 39938.989 | F14: =$B$5*(1+$B14)+$B$6*(1+F$12)+$B$7*(1+$B$9)+$B$8*(1+$B$10) -> 40508.969 | G14: =$B$5*(1+$B14)+$B$6*(1+G$12)+$B$7*(1+$B$9)+$B$8*(1+$B$10) -> 41078.949
B15: -0.15 | C15: =$B$5*(1+$B15)+$B$6*(1+C$12)+$B$7*(1+$B$9)+$B$8*(1+$B$10) -> 39999.805 | D15: =$B$5*(1+$B15)+$B$6*(1+D$12)+$B$7*(1+$B$9)+$B$8*(1+$B$10) -> 40569.785 | E15: =$B$5*(1+$B15)+$B$6*(1+E$12)+$B$7*(1+$B$9)+$B$8*(1+$B$10) -> 41139.765 | F15: =$B$5*(1+$B15)+$B$6*(1+F$12)+$B$7*(1+$B$9)+$B$8*(1+$B$10) -> 41709.745 | G15: =$B$5*(1+$B15)+$B$6*(1+G$12)+$B$7*(1+$B$9)+$B$8*(1+$B$10) -> 42279.725
B16: -0.1 | C16: =$B$5*(1+$B16)+$B$6*(1+C$12)+$B$7*(1+$B$9)+$B$8*(1+$B$10) -> 41200.582 | D16: =$B$5*(1+$B16)+$B$6*(1+D$12)+$B$7*(1+$B$9)+$B$8*(1+$B$10) -> 41770.562 | E16: =$B$5*(1+$B16)+$B$6*(1+E$12)+$B$7*(1+$B$9)+$B$8*(1+$B$10) -> 42340.542 | F16: =$B$5*(1+$B16)+$B$6*(1+F$12)+$B$7*(1+$B$9)+$B$8*(1+$B$10) -> 42910.522 | G16: =$B$5*(1+$B16)+$B$6*(1+G$12)+$B$7*(1+$B$9)+$B$8*(1+$B$10) -> 43480.502
B17: -0.05 | C17: =$B$5*(1+$B17)+$B$6*(1+C$12)+$B$7*(1+$B$9)+$B$8*(1+$B$10) -> 42401.358 | D17: =$B$5*(1+$B17)+$B$6*(1+D$12)+$B$7*(1+$B$9)+$B$8*(1+$B$10) -> 42971.338 | E17: =$B$5*(1+$B17)+$B$6*(1+E$12)+$B$7*(1+$B$9)+$B$8*(1+$B$10) -> 43541.318 | F17: =$B$5*(1+$B17)+$B$6*(1+F$12)+$B$7*(1+$B$9)+$B$8*(1+$B$10) -> 44111.298 | G17: =$B$5*(1+$B17)+$B$6*(1+G$12)+$B$7*(1+$B$9)+$B$8*(1+$B$10) -> 44681.278
B18: 0 | C18: =$B$5*(1+$B18)+$B$6*(1+C$12)+$B$7*(1+$B$9)+$B$8*(1+$B$10) -> 43602.135 | D18: =$B$5*(1+$B18)+$B$6*(1+D$12)+$B$7*(1+$B$9)+$B$8*(1+$B$10) -> 44172.115 | E18: =$B$5*(1+$B18)+$B$6*(1+E$12)+$B$7*(1+$B$9)+$B$8*(1+$B$10) -> 44742.095 | F18: =$B$5*(1+$B18)+$B$6*(1+F$12)+$B$7*(1+$B$9)+$B$8*(1+$B$10) -> 45312.075 | G18: =$B$5*(1+$B18)+$B$6*(1+G$12)+$B$7*(1+$B$9)+$B$8*(1+$B$10) -> 45882.055
B19: 0.05 | C19: =$B$5*(1+$B19)+$B$6*(1+C$12)+$B$7*(1+$B$9)+$B$8*(1+$B$10) -> 44802.911 | D19: =$B$5*(1+$B19)+$B$6*(1+D$12)+$B$7*(1+$B$9)+$B$8*(1+$B$10) -> 45372.891 | E19: =$B$5*(1+$B19)+$B$6*(1+E$12)+$B$7*(1+$B$9)+$B$8*(1+$B$10) -> 45942.871 | F19: =$B$5*(1+$B19)+$B$6*(1+F$12)+$B$7*(1+$B$9)+$B$8*(1+$B$10) -> 46512.851 | G19: =$B$5*(1+$B19)+$B$6*(1+G$12)+$B$7*(1+$B$9)+$B$8*(1+$B$10) -> 47082.831
A21: FY26E QCT + QTL revenue (for reference) | B21: =Summary!E13 -> 42477.24
A22: Shade guide: compare each cell with B21 to see which combinations grow revenue in FY27.

Sheet Checks
A1: Model Checks
A2: Every check should read OK.
A4: OVERALL | C4: =IF(COUNTIF(C7:C13,"OK")=7,"ALL OK","CHECK ERRORS") -> ALL OK
A6: # | B6: Check | C6: Result
A7: 1 | B7: QCT streams sum to reported QCT revenue (all actual quarters) | C7: =IF(SUMPRODUCT(ABS(Actuals!C9:M9+Actuals!C10:M10+Actuals!C11:M11-Actuals!C12:M12))<1,"OK","ERROR") -> OK
A8: 2 | B8: Guidance midpoints equal (low + high) / 2 | C8: =IF(SUMPRODUCT(ABS(Guidance!D11:N11-(Guidance!D9:N9+Guidance!D10:N10)/2))+SUMPRODUCT(ABS(Guidance!D16:N16-(Guidance!D14:N14+Guidance!D15:N15)/2))+SUMPRODUCT(ABS(Guidance!D21:N21-(Guidance!D19:N19+Guidance!D20:N20)/2))<1,"OK","ERROR") -> OK
A9: 3 | B9: Guidance low <= high for every quarter | C9: =IF(SUMPRODUCT(--(Guidance!D9:N9>Guidance!D10:N10))+SUMPRODUCT(--(Guidance!D14:N14>Guidance!D15:N15))+SUMPRODUCT(--(Guidance!D19:N19>Guidance!D20:N20))=0,"OK","ERROR") -> OK
A10: 4 | B10: Scenario selector is 1, 2 or 3 | C10: =IF(OR(Assumptions!B5=1,Assumptions!B5=2,Assumptions!B5=3),"OK","ERROR") -> OK
A11: 5 | B11: Summary annual revenue ties to quarterly Forecast | C11: =IF(ABS(SUM(Summary!C13:F13)-SUM(Forecast!C14:R14))<1,"OK","ERROR") -> OK
A12: 6 | B12: Active-scenario column in Scenarios ties to Summary FY27E | C12: =IF(ABS(INDEX(Scenarios!C17:E17,Assumptions!B5)-Summary!F13)<1,"OK","ERROR") -> OK
A13: 7 | B13: Forecast QCT = sum of forecast streams | C13: =IF(ABS(SUM(Forecast!N12:R12)-SUM(Forecast!N9:R11))<1,"OK","ERROR") -> OK
A15: Informational
B16: FY26 Q4 forecast QCT revenue vs. company guidance range | C16: =IF(Forecast!N12>Guidance!N15,"Above",IF(Forecast!N12<Guidance!N14,"Below","Within")) -> Within
B17: FY26 Q4 forecast QTL revenue vs. company guidance range | C17: =IF(Forecast!N13>Guidance!N20,"Above",IF(Forecast!N13<Guidance!N19,"Below","Within")) -> Within

Sheet Tableau_Revenue
A1: period | B1: fiscal_year | C1: fiscal_quarter | D1: period_sort | E1: type | F1: scenario | G1: segment | H1: stream | I1: revenue_musd | J1: stream_ebt_musd
A2: FY24 Q1 | B2: 2024 | C2: 1 | D2: 2024.1 | E2: =Forecast!C5 -> Actual | F2: =IF(E2="Actual","Reported",Assumptions!$C$5) -> Reported | G2: QCT | H2: Handsets | I2: =Forecast!C9 -> 6687
A3: FY24 Q1 | B3: 2024 | C3: 1 | D3: 2024.1 | E3: =Forecast!C5 -> Actual | F3: =IF(E3="Actual","Reported",Assumptions!$C$5) -> Reported | G3: QCT | H3: Automotive | I3: =Forecast!C10 -> 598
A4: FY24 Q1 | B4: 2024 | C4: 1 | D4: 2024.1 | E4: =Forecast!C5 -> Actual | F4: =IF(E4="Actual","Reported",Assumptions!$C$5) -> Reported | G4: QCT | H4: IoT | I4: =Forecast!C11 -> 1138
A5: FY24 Q1 | B5: 2024 | C5: 1 | D5: 2024.1 | E5: =Forecast!C5 -> Actual | F5: =IF(E5="Actual","Reported",Assumptions!$C$5) -> Reported | G5: QTL | H5: Licensing | I5: =Forecast!C13 -> 1460 | J5: =Forecast!C18 -> 1080
A6: FY24 Q2 | B6: 2024 | C6: 2 | D6: 2024.2 | E6: =Forecast!D5 -> Actual | F6: =IF(E6="Actual","Reported",Assumptions!$C$5) -> Reported | G6: QCT | H6: Handsets | I6: =Forecast!D9 -> 6180
A7: FY24 Q2 | B7: 2024 | C7: 2 | D7: 2024.2 | E7: =Forecast!D5 -> Actual | F7: =IF(E7="Actual","Reported",Assumptions!$C$5) -> Reported | G7: QCT | H7: Automotive | I7: =Forecast!D10 -> 603
A8: FY24 Q2 | B8: 2024 | C8: 2 | D8: 2024.2 | E8: =Forecast!D5 -> Actual | F8: =IF(E8="Actual","Reported",Assumptions!$C$5) -> Reported | G8: QCT | H8: IoT | I8: =Forecast!D11 -> 1243
A9: FY24 Q2 | B9: 2024 | C9: 2 | D9: 2024.2 | E9: =Forecast!D5 -> Actual | F9: =IF(E9="Actual","Reported",Assumptions!$C$5) -> Reported | G9: QTL | H9: Licensing | I9: =Forecast!D13 -> 1318 | J9: =Forecast!D18 -> 933
A10: FY24 Q3 | B10: 2024 | C10: 3 | D10: 2024.3 | E10: =Forecast!E5 -> Actual | F10: =IF(E10="Actual","Reported",Assumptions!$C$5) -> Reported | G10: QCT | H10: Handsets | I10: =Forecast!E9 -> 5899
A11: FY24 Q3 | B11: 2024 | C11: 3 | D11: 2024.3 | E11: =Forecast!E5 -> Actual | F11: =IF(E11="Actual","Reported",Assumptions!$C$5) -> Reported | G11: QCT | H11: Automotive | I11: =Forecast!E10 -> 811
A12: FY24 Q3 | B12: 2024 | C12: 3 | D12: 2024.3 | E12: =Forecast!E5 -> Actual | F12: =IF(E12="Actual","Reported",Assumptions!$C$5) -> Reported | G12: QCT | H12: IoT | I12: =Forecast!E11 -> 1359
A13: FY24 Q3 | B13: 2024 | C13: 3 | D13: 2024.3 | E13: =Forecast!E5 -> Actual | F13: =IF(E13="Actual","Reported",Assumptions!$C$5) -> Reported | G13: QTL | H13: Licensing | I13: =Forecast!E13 -> 1273 | J13: =Forecast!E18 -> 894
A14: FY24 Q4 | B14: 2024 | C14: 4 | D14: 2024.4 | E14: =Forecast!F5 -> Actual | F14: =IF(E14="Actual","Reported",Assumptions!$C$5) -> Reported | G14: QCT | H14: Handsets | I14: =Forecast!F9 -> 6096
A15: FY24 Q4 | B15: 2024 | C15: 4 | D15: 2024.4 | E15: =Forecast!F5 -> Actual | F15: =IF(E15="Actual","Reported",Assumptions!$C$5) -> Reported | G15: QCT | H15: Automotive | I15: =Forecast!F10 -> 899
A16: FY24 Q4 | B16: 2024 | C16: 4 | D16: 2024.4 | E16: =Forecast!F5 -> Actual | F16: =IF(E16="Actual","Reported",Assumptions!$C$5) -> Reported | G16: QCT | H16: IoT | I16: =Forecast!F11 -> 1683
A17: FY24 Q4 | B17: 2024 | C17: 4 | D17: 2024.4 | E17: =Forecast!F5 -> Actual | F17: =IF(E17="Actual","Reported",Assumptions!$C$5) -> Reported | G17: QTL | H17: Licensing | I17: =Forecast!F13 -> 1521 | J17: =Forecast!F18 -> 1120
A18: FY25 Q1 | B18: 2025 | C18: 1 | D18: 2025.1 | E18: =Forecast!G5 -> Actual | F18: =IF(E18="Actual","Reported",Assumptions!$C$5) -> Reported | G18: QCT | H18: Handsets | I18: =Forecast!G9 -> 7574
A19: FY25 Q1 | B19: 2025 | C19: 1 | D19: 2025.1 | E19: =Forecast!G5 -> Actual | F19: =IF(E19="Actual","Reported",Assumptions!$C$5) -> Reported | G19: QCT | H19: Automotive | I19: =Forecast!G10 -> 961
A20: FY25 Q1 | B20: 2025 | C20: 1 | D20: 2025.1 | E20: =Forecast!G5 -> Actual | F20: =IF(E20="Actual","Reported",Assumptions!$C$5) -> Reported | G20: QCT | H20: IoT | I20: =Forecast!G11 -> 1549
A21: FY25 Q1 | B21: 2025 | C21: 1 | D21: 2025.1 | E21: =Forecast!G5 -> Actual | F21: =IF(E21="Actual","Reported",Assumptions!$C$5) -> Reported | G21: QTL | H21: Licensing | I21: =Forecast!G13 -> 1535 | J21: =Forecast!G18 -> 1158
A22: FY25 Q2 | B22: 2025 | C22: 2 | D22: 2025.2 | E22: =Forecast!H5 -> Actual | F22: =IF(E22="Actual","Reported",Assumptions!$C$5) -> Reported | G22: QCT | H22: Handsets | I22: =Forecast!H9 -> 6929
A23: FY25 Q2 | B23: 2025 | C23: 2 | D23: 2025.2 | E23: =Forecast!H5 -> Actual | F23: =IF(E23="Actual","Reported",Assumptions!$C$5) -> Reported | G23: QCT | H23: Automotive | I23: =Forecast!H10 -> 959
A24: FY25 Q2 | B24: 2025 | C24: 2 | D24: 2025.2 | E24: =Forecast!H5 -> Actual | F24: =IF(E24="Actual","Reported",Assumptions!$C$5) -> Reported | G24: QCT | H24: IoT | I24: =Forecast!H11 -> 1581
A25: FY25 Q2 | B25: 2025 | C25: 2 | D25: 2025.2 | E25: =Forecast!H5 -> Actual | F25: =IF(E25="Actual","Reported",Assumptions!$C$5) -> Reported | G25: QTL | H25: Licensing | I25: =Forecast!H13 -> 1319 | J25: =Forecast!H18 -> 929
A26: FY25 Q3 | B26: 2025 | C26: 3 | D26: 2025.3 | E26: =Forecast!I5 -> Actual | F26: =IF(E26="Actual","Reported",Assumptions!$C$5) -> Reported | G26: QCT | H26: Handsets | I26: =Forecast!I9 -> 6328
A27: FY25 Q3 | B27: 2025 | C27: 3 | D27: 2025.3 | E27: =Forecast!I5 -> Actual | F27: =IF(E27="Actual","Reported",Assumptions!$C$5) -> Reported | G27: QCT | H27: Automotive | I27: =Forecast!I10 -> 984
A28: FY25 Q3 | B28: 2025 | C28: 3 | D28: 2025.3 | E28: =Forecast!I5 -> Actual | F28: =IF(E28="Actual","Reported",Assumptions!$C$5) -> Reported | G28: QCT | H28: IoT | I28: =Forecast!I11 -> 1681
A29: FY25 Q3 | B29: 2025 | C29: 3 | D29: 2025.3 | E29: =Forecast!I5 -> Actual | F29: =IF(E29="Actual","Reported",Assumptions!$C$5) -> Reported | G29: QTL | H29: Licensing | I29: =Forecast!I13 -> 1318 | J29: =Forecast!I18 -> 942
A30: FY25 Q4 | B30: 2025 | C30: 4 | D30: 2025.4 | E30: =Forecast!J5 -> Actual | F30: =IF(E30="Actual","Reported",Assumptions!$C$5) -> Reported | G30: QCT | H30: Handsets | I30: =Forecast!J9 -> 6961
A31: FY25 Q4 | B31: 2025 | C31: 4 | D31: 2025.4 | E31: =Forecast!J5 -> Actual | F31: =IF(E31="Actual","Reported",Assumptions!$C$5) -> Reported | G31: QCT | H31: Automotive | I31: =Forecast!J10 -> 1053
A32: FY25 Q4 | B32: 2025 | C32: 4 | D32: 2025.4 | E32: =Forecast!J5 -> Actual | F32: =IF(E32="Actual","Reported",Assumptions!$C$5) -> Reported | G32: QCT | H32: IoT | I32: =Forecast!J11 -> 1807
A33: FY25 Q4 | B33: 2025 | C33: 4 | D33: 2025.4 | E33: =Forecast!J5 -> Actual | F33: =IF(E33="Actual","Reported",Assumptions!$C$5) -> Reported | G33: QTL | H33: Licensing | I33: =Forecast!J13 -> 1409 | J33: =Forecast!J18 -> 1015
A34: FY26 Q1 | B34: 2026 | C34: 1 | D34: 2026.1 | E34: =Forecast!K5 -> Actual | F34: =IF(E34="Actual","Reported",Assumptions!$C$5) -> Reported | G34: QCT | H34: Handsets | I34: =Forecast!K9 -> 7824
A35: FY26 Q1 | B35: 2026 | C35: 1 | D35: 2026.1 | E35: =Forecast!K5 -> Actual | F35: =IF(E35="Actual","Reported",Assumptions!$C$5) -> Reported | G35: QCT | H35: Automotive | I35: =Forecast!K10 -> 1101
A36: FY26 Q1 | B36: 2026 | C36: 1 | D36: 2026.1 | E36: =Forecast!K5 -> Actual | F36: =IF(E36="Actual","Reported",Assumptions!$C$5) -> Reported | G36: QCT | H36: IoT | I36: =Forecast!K11 -> 1688
A37: FY26 Q1 | B37: 2026 | C37: 1 | D37: 2026.1 | E37: =Forecast!K5 -> Actual | F37: =IF(E37="Actual","Reported",Assumptions!$C$5) -> Reported | G37: QTL | H37: Licensing | I37: =Forecast!K13 -> 1592 | J37: =Forecast!K18 -> 1231
A38: FY26 Q2 | B38: 2026 | C38: 2 | D38: 2026.2 | E38: =Forecast!L5 -> Actual | F38: =IF(E38="Actual","Reported",Assumptions!$C$5) -> Reported | G38: QCT | H38: Handsets | I38: =Forecast!L9 -> 6024
A39: FY26 Q2 | B39: 2026 | C39: 2 | D39: 2026.2 | E39: =Forecast!L5 -> Actual | F39: =IF(E39="Actual","Reported",Assumptions!$C$5) -> Reported | G39: QCT | H39: Automotive | I39: =Forecast!L10 -> 1326
A40: FY26 Q2 | B40: 2026 | C40: 2 | D40: 2026.2 | E40: =Forecast!L5 -> Actual | F40: =IF(E40="Actual","Reported",Assumptions!$C$5) -> Reported | G40: QCT | H40: IoT | I40: =Forecast!L11 -> 1726
...

Sheet Tableau_Guidance
A1: period | B1: fiscal_year | C1: fiscal_quarter | D1: period_sort | E1: segment | F1: type | G1: value_musd | H1: guide_low_musd | I1: guide_high_musd | J1: guide_mid_musd | K1: variance_vs_mid_pct | L1: position
A2: FY24 Q2 | B2: 2024 | C2: 2 | D2: 2024.2 | E2: QCT | F2: =Forecast!D5 -> Actual | G2: =Forecast!D12 -> 8026 | H2: =Guidance!D14 -> 7600 | I2: =Guidance!D15 -> 8200 | J2: =Guidance!D16 -> 7900 | K2: =IF(J2=0,0,G2/J2-1) -> 0.015949367 | L2: =IF(G2>I2,"Above",IF(G2<H2,"Below","Within")) -> Within
A3: FY24 Q2 | B3: 2024 | C3: 2 | D3: 2024.2 | E3: QTL | F3: =Forecast!D5 -> Actual | G3: =Forecast!D13 -> 1318 | H3: =Guidance!D19 -> 1200 | I3: =Guidance!D20 -> 1400 | J3: =Guidance!D21 -> 1300 | K3: =IF(J3=0,0,G3/J3-1) -> 0.013846154 | L3: =IF(G3>I3,"Above",IF(G3<H3,"Below","Within")) -> Within
A4: FY24 Q3 | B4: 2024 | C4: 3 | D4: 2024.3 | E4: QCT | F4: =Forecast!E5 -> Actual | G4: =Forecast!E12 -> 8069 | H4: =Guidance!E14 -> 7500 | I4: =Guidance!E15 -> 8100 | J4: =Guidance!E16 -> 7800 | K4: =IF(J4=0,0,G4/J4-1) -> 0.034487179 | L4: =IF(G4>I4,"Above",IF(G4<H4,"Below","Within")) -> Within
A5: FY24 Q3 | B5: 2024 | C5: 3 | D5: 2024.3 | E5: QTL | F5: =Forecast!E5 -> Actual | G5: =Forecast!E13 -> 1273 | H5: =Guidance!E19 -> 1200 | I5: =Guidance!E20 -> 1400 | J5: =Guidance!E21 -> 1300 | K5: =IF(J5=0,0,G5/J5-1) -> -0.020769231 | L5: =IF(G5>I5,"Above",IF(G5<H5,"Below","Within")) -> Within
A6: FY24 Q4 | B6: 2024 | C6: 4 | D6: 2024.4 | E6: QCT | F6: =Forecast!F5 -> Actual | G6: =Forecast!F12 -> 8678 | H6: =Guidance!F14 -> 8100 | I6: =Guidance!F15 -> 8700 | J6: =Guidance!F16 -> 8400 | K6: =IF(J6=0,0,G6/J6-1) -> 0.033095238 | L6: =IF(G6>I6,"Above",IF(G6<H6,"Below","Within")) -> Within
A7: FY24 Q4 | B7: 2024 | C7: 4 | D7: 2024.4 | E7: QTL | F7: =Forecast!F5 -> Actual | G7: =Forecast!F13 -> 1521 | H7: =Guidance!F19 -> 1350 | I7: =Guidance!F20 -> 1550 | J7: =Guidance!F21 -> 1450 | K7: =IF(J7=0,0,G7/J7-1) -> 0.048965517 | L7: =IF(G7>I7,"Above",IF(G7<H7,"Below","Within")) -> Within
A8: FY25 Q1 | B8: 2025 | C8: 1 | D8: 2025.1 | E8: QCT | F8: =Forecast!G5 -> Actual | G8: =Forecast!G12 -> 10084 | H8: =Guidance!G14 -> 9000 | I8: =Guidance!G15 -> 9600 | J8: =Guidance!G16 -> 9300 | K8: =IF(J8=0,0,G8/J8-1) -> 0.084301075 | L8: =IF(G8>I8,"Above",IF(G8<H8,"Below","Within")) -> Above
A9: FY25 Q1 | B9: 2025 | C9: 1 | D9: 2025.1 | E9: QTL | F9: =Forecast!G5 -> Actual | G9: =Forecast!G13 -> 1535 | H9: =Guidance!G19 -> 1450 | I9: =Guidance!G20 -> 1650 | J9: =Guidance!G21 -> 1550 | K9: =IF(J9=0,0,G9/J9-1) -> -0.0096774194 | L9: =IF(G9>I9,"Above",IF(G9<H9,"Below","Within")) -> Within
A10: FY25 Q2 | B10: 2025 | C10: 2 | D10: 2025.2 | E10: QCT | F10: =Forecast!H5 -> Actual | G10: =Forecast!H12 -> 9469 | H10: =Guidance!H14 -> 8900 | I10: =Guidance!H15 -> 9500 | J10: =Guidance!H16 -> 9200 | K10: =IF(J10=0,0,G10/J10-1) -> 0.02923913 | L10: =IF(G10>I10,"Above",IF(G10<H10,"Below","Within")) -> Within
A11: FY25 Q2 | B11: 2025 | C11: 2 | D11: 2025.2 | E11: QTL | F11: =Forecast!H5 -> Actual | G11: =Forecast!H13 -> 1319 | H11: =Guidance!H19 -> 1250 | I11: =Guidance!H20 -> 1450 | J11: =Guidance!H21 -> 1350 | K11: =IF(J11=0,0,G11/J11-1) -> -0.022962963 | L11: =IF(G11>I11,"Above",IF(G11<H11,"Below","Within")) -> Within
A12: FY25 Q3 | B12: 2025 | C12: 3 | D12: 2025.3 | E12: QCT | F12: =Forecast!I5 -> Actual | G12: =Forecast!I12 -> 8993 | H12: =Guidance!I14 -> 8700 | I12: =Guidance!I15 -> 9300 | J12: =Guidance!I16 -> 9000 | K12: =IF(J12=0,0,G12/J12-1) -> -0.00077777778 | L12: =IF(G12>I12,"Above",IF(G12<H12,"Below","Within")) -> Within
A13: FY25 Q3 | B13: 2025 | C13: 3 | D13: 2025.3 | E13: QTL | F13: =Forecast!I5 -> Actual | G13: =Forecast!I13 -> 1318 | H13: =Guidance!I19 -> 1150 | I13: =Guidance!I20 -> 1350 | J13: =Guidance!I21 -> 1250 | K13: =IF(J13=0,0,G13/J13-1) -> 0.0544 | L13: =IF(G13>I13,"Above",IF(G13<H13,"Below","Within")) -> Within
A14: FY25 Q4 | B14: 2025 | C14: 4 | D14: 2025.4 | E14: QCT | F14: =Forecast!J5 -> Actual | G14: =Forecast!J12 -> 9821 | H14: =Guidance!J14 -> 9000 | I14: =Guidance!J15 -> 9600 | J14: =Guidance!J16 -> 9300 | K14: =IF(J14=0,0,G14/J14-1) -> 0.056021505 | L14: =IF(G14>I14,"Above",IF(G14<H14,"Below","Within")) -> Above
A15: FY25 Q4 | B15: 2025 | C15: 4 | D15: 2025.4 | E15: QTL | F15: =Forecast!J5 -> Actual | G15: =Forecast!J13 -> 1409 | H15: =Guidance!J19 -> 1250 | I15: =Guidance!J20 -> 1450 | J15: =Guidance!J21 -> 1350 | K15: =IF(J15=0,0,G15/J15-1) -> 0.043703704 | L15: =IF(G15>I15,"Above",IF(G15<H15,"Below","Within")) -> Within
A16: FY26 Q1 | B16: 2026 | C16: 1 | D16: 2026.1 | E16: QCT | F16: =Forecast!K5 -> Actual | G16: =Forecast!K12 -> 10613 | H16: =Guidance!K14 -> 10300 | I16: =Guidance!K15 -> 10900 | J16: =Guidance!K16 -> 10600 | K16: =IF(J16=0,0,G16/J16-1) -> 0.0012264151 | L16: =IF(G16>I16,"Above",IF(G16<H16,"Below","Within")) -> Within
A17: FY26 Q1 | B17: 2026 | C17: 1 | D17: 2026.1 | E17: QTL | F17: =Forecast!K5 -> Actual | G17: =Forecast!K13 -> 1592 | H17: =Guidance!K19 -> 1400 | I17: =Guidance!K20 -> 1600 | J17: =Guidance!K21 -> 1500 | K17: =IF(J17=0,0,G17/J17-1) -> 0.061333333 | L17: =IF(G17>I17,"Above",IF(G17<H17,"Below","Within")) -> Within
A18: FY26 Q2 | B18: 2026 | C18: 2 | D18: 2026.2 | E18: QCT | F18: =Forecast!L5 -> Actual | G18: =Forecast!L12 -> 9076 | H18: =Guidance!L14 -> 8800 | I18: =Guidance!L15 -> 9400 | J18: =Guidance!L16 -> 9100 | K18: =IF(J18=0,0,G18/J18-1) -> -0.0026373626 | L18: =IF(G18>I18,"Above",IF(G18<H18,"Below","Within")) -> Within
A19: FY26 Q2 | B19: 2026 | C19: 2 | D19: 2026.2 | E19: QTL | F19: =Forecast!L5 -> Actual | G19: =Forecast!L13 -> 1382 | H19: =Guidance!L19 -> 1200 | I19: =Guidance!L20 -> 1400 | J19: =Guidance!L21 -> 1300 | K19: =IF(J19=0,0,G19/J19-1) -> 0.063076923 | L19: =IF(G19>I19,"Above",IF(G19<H19,"Below","Within")) -> Within
A20: FY26 Q3 | B20: 2026 | C20: 3 | D20: 2026.3 | E20: QCT | F20: =Forecast!M5 -> Actual | G20: =Forecast!M12 -> 8504 | H20: =Guidance!M14 -> 7900 | I20: =Guidance!M15 -> 8500 | J20: =Guidance!M16 -> 8200 | K20: =IF(J20=0,0,G20/J20-1) -> 0.037073171 | L20: =IF(G20>I20,"Above",IF(G20<H20,"Below","Within")) -> Above
A21: FY26 Q3 | B21: 2026 | C21: 3 | D21: 2026.3 | E21: QTL | F21: =Forecast!M5 -> Actual | G21: =Forecast!M13 -> 1278 | H21: =Guidance!M19 -> 1150 | I21: =Guidance!M20 -> 1350 | J21: =Guidance!M21 -> 1250 | K21: =IF(J21=0,0,G21/J21-1) -> 0.0224 | L21: =IF(G21>I21,"Above",IF(G21<H21,"Below","Within")) -> Within
A22: FY26 Q4 | B22: 2026 | C22: 4 | D22: 2026.4 | E22: QCT | F22: =Forecast!N5 -> Forecast | G22: =Forecast!N12 -> 8735.96 | H22: =Guidance!N14 -> 8400 | I22: =Guidance!N15 -> 9000 | J22: =Guidance!N16 -> 8700 | K22: =IF(J22=0,0,G22/J22-1) -> 0.0041333333 | L22: =IF(G22>I22,"Above",IF(G22<H22,"Below","Within")) -> Within
A23: FY26 Q4 | B23: 2026 | C23: 4 | D23: 2026.4 | E23: QTL | F23: =Forecast!N5 -> Forecast | G23: =Forecast!N13 -> 1296.28 | H23: =Guidance!N19 -> 1200 | I23: =Guidance!N20 -> 1400 | J23: =Guidance!N21 -> 1300 | K23: =IF(J23=0,0,G23/J23-1) -> -0.0028615385 | L23: =IF(G23>I23,"Above",IF(G23<H23,"Below","Within")) -> Within
